<?xml version="1.0" ?>
<robot name="turtlebot3_waffle_pi_for_open_manipulator" xmlns:xacro="http://ros.org/wiki/xacro">
  <xacro:include filename="$(find mm_robot_description)/urdf/common_properties.xacro"/>
  <xacro:include filename="$(find mm_robot_description)/urdf/turtlebot3_waffle_pi_for_open_manipulator.gazebo.xacro"/>
  <xacro:property name="mf" value="2"/>

  <link name="base_footprint"/>

  <joint name="base_joint" type="fixed">
    <parent link="base_footprint"/>
    <child link="base_link" />
    <origin xyz="0 0 ${0.010*2}" rpy="0 0 0"/>
  </joint>

  <link name="base_link">
    <visual>
      <origin xyz="${-0.064*mf} 0 0.0" rpy="0 0 0"/>
      <geometry>
        <mesh filename="package://mm_robot_description/meshes/bases/waffle_pi_base_for_open_manipulator.stl" scale="${0.001*mf} ${0.001*mf} ${0.001*mf}"/>
      </geometry>
      <material name="light_black"/>
    </visual>

    <collision>
      <origin xyz="${-0.064*mf} 0 ${0.047*mf}" rpy="0 0 0"/>
      <geometry>
        <box size="${mf*0.266} ${mf*0.266} ${mf*0.094}"/>
      </geometry>
    </collision>

    <inertial>
      <origin xyz="0.0 0 0.0" rpy="0 0 0"/>
      <mass value="${mf*1.6329594e+00}"/>
      <inertia ixx="${mf*mf*mf*1.0}" ixy="0.0" ixz="0.0"
               iyy="${mf*mf*mf*1.0}" iyz="0.0"
               izz="${mf*mf*mf*1.0}" />
      <!-- <inertia ixx="8.7002718e-03" ixy="-4.7576583e-05" ixz="1.1160499e-04"
               iyy="8.6195418e-03" iyz="-3.5422299e-06"
               izz="1.4612727e-02" />                -->
    </inertial>
  </link>

  <joint name="wheel_left_joint" type="continuous">
    <parent link="base_link"/>
    <child link="wheel_left_link"/>
    <origin xyz="0.0 ${mf*0.144} ${0.023*mf}" rpy="-1.57 0 0"/>
    <axis xyz="0 0 1"/>
  </joint>

  <link name="wheel_left_link">
    <visual>
      <origin xyz="0 0 0" rpy="1.57 0 0"/>
      <geometry>
        <mesh filename="package://mm_robot_description/meshes/wheels/left_tire.stl" scale="${0.001*mf} ${0.001*mf} ${0.001*mf}"/>
      </geometry>
      <material name="dark"/>
    </visual>

    <collision>
      <origin xyz="0 0 0" rpy="0 0 0"/>
      <geometry>
        <cylinder length="${mf*0.018}" radius="${mf*0.033}"/>
      </geometry>
    </collision>

    <inertial>
      <origin xyz="0 0 0" />
      <mass value="${mf*2.8498940e-02}" />
      <inertia ixx="${mf*mf*mf*1.1175580e-05}" ixy="${mf*mf*mf*-4.2369783e-11}" ixz="${mf*mf*mf*-5.9381719e-09}"
               iyy="${mf*mf*mf*1.1192413e-05}" iyz="${mf*mf*mf*-1.4400107e-11}"
               izz="${mf*mf*mf*2.0712558e-05}" />
      </inertial>
  </link>

  <joint name="wheel_right_joint" type="continuous">
    <parent link="base_link"/>
    <child link="wheel_right_link"/>
    <origin xyz="0.0 ${mf*-0.144} ${mf*0.023}" rpy="-1.57 0 0"/>
    <axis xyz="0 0 1"/>
  </joint>

  <link name="wheel_right_link">
    <visual>
      <origin xyz="0 0 0" rpy="1.57 0 0"/>
      <geometry>
        <mesh filename="package://mm_robot_description/meshes/wheels/right_tire.stl" scale="${0.001*mf} ${0.001*mf} ${0.001*mf}"/>
      </geometry>
      <material name="dark"/>
    </visual>

    <collision>
      <origin xyz="0 ${mf*0.001} 0" rpy="0 0 0"/>
      <geometry>
        <cylinder length="${mf*0.018}" radius="${mf*0.033}"/>
      </geometry>
    </collision>

    <inertial>
      <origin xyz="0 0 0" />
      <mass value="${mf*2.8498940e-02}" />
      <inertia ixx="${mf*mf*mf*1.1175580e-05}" ixy="${mf*mf*mf*-4.2369783e-11}" ixz="${mf*mf*mf*-5.9381719e-09}"
               iyy="${mf*mf*mf*1.1192413e-05}" iyz="${mf*mf*mf*-1.4400107e-11}"
               izz="${mf*mf*mf*2.0712558e-05}" />
      </inertial>
  </link>

  <joint name="caster_back_right_joint" type="fixed">
    <parent link="base_link"/>
    <child link="caster_back_right_link"/>
    <origin xyz="${mf*-0.177} ${mf*-0.064} ${mf*-0.004}" rpy="-1.57 0 0"/>
  </joint>

  <link name="caster_back_right_link">
    <collision>
      <origin xyz="0 ${mf*0.001} 0" rpy="0 0 0"/>
      <geometry>
        <box size="${mf*0.030} ${mf*0.009} ${mf*0.020}"/>
      </geometry>
    </collision>

    <inertial>
      <origin xyz="0 0 0" />
      <mass value="${mf*0.005}" />
      <inertia ixx="${mf*mf*mf*0.001}" ixy="0.0" ixz="0.0"
               iyy="${mf*mf*mf*0.001}" iyz="0.0"
               izz="${mf*mf*mf*0.001}" />
    </inertial>
  </link>

  <joint name="caster_back_left_joint" type="fixed">
    <parent link="base_link"/>
    <child link="caster_back_left_link"/>
    <origin xyz="${mf*-0.177} ${mf*0.064} ${mf*-0.004}" rpy="-1.57 0 0"/>
  </joint>

  <link name="caster_back_left_link">
    <collision>
      <origin xyz="0 ${mf*0.001} 0" rpy="0 0 0"/>
      <geometry>
        <box size="${mf*0.030} ${mf*0.009} ${mf*0.020}"/>
      </geometry>
    </collision>

    <inertial>
      <origin xyz="0 0 0" />
      <mass value="${mf*0.005}" />
      <inertia ixx="${mf*mf*mf*0.001}" ixy="0.0" ixz="0.0"
               iyy="${mf*mf*mf*0.001}" iyz="0.0"
               izz="${mf*mf*mf*0.001}" />
    </inertial>
  </link>

</robot>
